<mujoco model="j2s7s300">
    <compiler angle="radian" meshdir="meshes/" />


    <asset>

        <mesh file="base.STL" name="base" />
        <mesh file="shoulder.STL" name="link_1" />
        <mesh file="arm_half_1.STL" name="link_2" />
        <mesh file="arm_half_2.STL" name="link_3" />
        <mesh file="forearm.STL" name="link_4" />
        <mesh file="wrist_spherical_1.STL" name="link_5" />
        <mesh file="wrist_spherical_2.STL" name="link_6" />
        <mesh file="hand_3finger.STL" name="link_7" />

        <mesh file="finger_distal.STL" name="finger_distal" />
        <mesh file="finger_proximal.STL" name="finger_proximal" />
        
        
        

        
        <mesh file="Vase1M.stl" name="Vase1M" scale="0.001 0.001 0.001" />

        <texture builtin="gradient" height="100" rgb1=".4 .5 .6" rgb2="1 1 1" type="skybox" width="100" />
        <texture builtin="checker" height="100" mark="none" markrgb=".8 .8 .8" name="groundplane" rgb1=".25 .26 .25" rgb2=".22 .22 .22" type="2d" width="100" />

        <material name="MatViz" reflectance="0.5" rgba=".07 .07 .1 1" shininess=".1" specular="1" />
        <material name="MatGnd" reflectance="0.00001" shininess=".3" specular="1" texrepeat="5 5" texture="groundplane" />
    </asset>

    <default>
        <geom margin="0.001" />
        <joint armature=".01" damping="0.2" limited="false" />


        <default class="ground">
            <geom conaffinity="1" contype="0" material="MatGnd" type="plane" />
        </default>
    </default>

    <worldbody>
        <body name="root" pos="0 0 0">

            <camera euler="0 0 3.14" mode="fixed" name="camera" pos="0 0 1" />
            <body euler="-1.57 0.0 -1.57" name="j2s7s300_link_7" pos="0.0 0.18 0.0654">
                <inertial diaginertia="0.00034532 0.00034532 0.00058160" mass="0.727" pos="0 0 -0.06" />

                <joint axis="0 1 0" limited="true" name="j2s7s300_slide_x" pos="0 0 0" range="-0.5 0.5" type="slide" />
                <joint axis="0 0 1" limited="true" name="j2s7s300_slide_y" pos="0 0 0" range="-0.5 0.5" type="slide" />
                <joint axis="1 0 0" limited="true" name="j2s7s300_slide_z" pos="0 0 0" range="-0.5 0.5" type="slide" />
                <geom mesh="link_7" name="palm" rgba="0.792157 0.819608 0.933333 1" type="mesh" />
                <site name="palm" pos="0.0 0.0 -0.11" quat="0 1 0 0" rgba="25 0.5 0.7 1" size="0.005 0.005 0.005" type="cylinder" />
                <site name="palm_1" pos="0.02 0.0 -0.11" quat="0 1 0 0" rgba="25 0.5 0.7 1" size="0.005 0.005 0.005" type="cylinder" />
                <site name="palm_2" pos="-0.02 0.0 -0.11" quat="0 1 0 0" rgba="25 0.5 0.7 1" size="0.005 0.005 0.005" type="cylinder" />
                <site name="palm_3" pos="0.0 -0.015 -0.11" quat="0 1 0 0" rgba="25 0.5 0.7 1" size="0.005 0.005 0.005" type="cylinder" />
                <site name="palm_4" pos="0.0 0.015 -0.11" quat="0 1 0 0" rgba="25 0.5 0.7 1" size="0.005 0.005 0.005" type="cylinder" />


                
                <body euler="1.57079924 -1.35961082 -2.23052837" name="j2s7s300_link_finger_1" pos="0.00279 0.03126 -0.11467">
                    <inertial diaginertia="7.89997e-07 7.89997e-07 8e-08" mass="0.01" pos="0.022 0 0" />
                    <joint axis="0 0 1" limited="true" name="j2s7s300_joint_finger_1" pos="0 0 0" range="0 2" />
                    <geom mesh="finger_proximal" name="f1_prox" rgba="0.792157 0.819608 0.933333 1" type="mesh" />
                    <site euler="1.57 3.14 1.57" name="f1_prox" pos="0.03 0 0" rgba="25 0.5 0.7 1" size="0.002 0.002 0.002" type="cylinder" />
                    <site euler="1.57 3.14 1.57" name="f1_prox_1" pos="0.02 0 0" rgba="25 0.5 0.7 1" size="0.002 0.002 0.002" type="cylinder" />


                    <body name="j2s7s300_link_finger_tip_1" pos="0.044 -0.003 0">
                        <inertial diaginertia="7.89997e-07 7.89997e-07 8e-08" mass="0.01" pos="0.022 0 0" />
                        <joint axis="0 0 1" name="j2s7s300_joint_fingertip_1" pos="0 0 0" range="0 2" />
                        <geom mesh="finger_distal" name="f1_dist" rgba="0.792157 0.819608 0.933333 1" type="mesh" />
                        <site euler="1.57 3.14 1.57" name="f1_dist" pos="0.03 0.0 0.0" rgba="25 0.5 0.7 1" size="0.002 0.002 0.002" type="cylinder" />
                        <site euler="1.57 3.14 1.57" name="f1_dist_1" pos="0.02 0.0 0.0" rgba="25 0.5 0.7 1" size="0.002 0.002 0.002" type="cylinder" />


                    </body>


                </body>

                
                <body name="j2s7s300_link_finger_2" pos="0.02226 -0.02707 -0.11482" quat="0.659653 -0.37146 0.601679 -0.254671">
                    <inertial diaginertia="7.89997e-07 7.89997e-07 8e-08" mass="0.01" pos="0.022 0 0" />
                    <joint axis="0 0 1" limited="true" name="j2s7s300_joint_finger_2" pos="0 0 0" range="0 2" />
                    <geom mesh="finger_proximal" name="f2_prox" rgba="0.792157 0.819608 0.933333 1" type="mesh" />
                    <site euler="1.57 3.14 1.57" name="f2_prox" pos="0.03 0 0" rgba="25 0.5 0.7 1" size="0.002 0.002 0.002" type="cylinder" />
                    <site euler="1.57 3.14 1.57" name="f2_prox_1" pos="0.02 0 0" rgba="25 0.5 0.7 1" size="0.002 0.002 0.002" type="cylinder" />


                    <body name="j2s7s300_link_finger_tip_2" pos="0.044 -0.003 0">
                        <inertial diaginertia="7.89997e-07 7.89997e-07 8e-08" mass="0.01" pos="0.022 0 0" />
                        <joint axis="0 0 1" name="j2s7s300_joint_fingertip_2" pos="0 0 0" range="0 2" />
                        <geom mesh="finger_distal" name="f2_dist" rgba="0.792157 0.819608 0.933333 1" type="mesh" />
                        <site euler="1.57 3.14 1.57" name="f2_dist" pos="0.03 0 0" rgba="25 0.5 0.7 1" size="0.002 0.002 0.002" type="cylinder" />
                        <site euler="1.57 3.14 1.57" name="f2_dist_1" pos="0.02 0 0" rgba="25 0.5 0.7 1" size="0.002 0.002 0.002" type="cylinder" />

                    </body>


                </body>

                
                <body name="j2s7s300_link_finger_3" pos="-0.02226 -0.02707 -0.11482" quat="0.601679 -0.254671 0.659653 -0.37146">
                    <inertial diaginertia="7.89997e-07 7.89997e-07 8e-08" mass="0.01" pos="0.022 0 0" />
                    <joint axis="0 0 1" limited="true" name="j2s7s300_joint_finger_3" pos="0 0 0" range="0 2" />
                    <geom mesh="finger_proximal" name="f3_prox" rgba="0.792157 0.819608 0.933333 1" type="mesh" />
                    <site euler="1.57 3.14 1.57" name="f3_prox" pos="0.03 0 0" rgba="25 0.5 0.7 1" size="0.002 0.002 0.002" type="cylinder" />
                    <site euler="1.57 3.14 1.57" name="f3_prox_1" pos="0.02 0 0" rgba="25 0.5 0.7 1" size="0.002 0.002 0.002" type="cylinder" />


                    <body name="j2s7s300_link_finger_tip_3" pos="0.044 -0.003 0">
                        <inertial diaginertia="7.89997e-07 7.89997e-07 8e-08" mass="0.01" pos="0.022 0 0" />
                        <joint axis="0 0 1" name="j2s7s300_joint_fingertip_3" pos="0 0 0" range="0 2" />
                        <geom mesh="finger_distal" name="f3_dist" rgba="0.792157 0.819608 0.933333 1" type="mesh" />
                        <site euler="1.57 3.14 1.57" name="f3_dist" pos="0.03 0 0" rgba="25 0.5 0.7 1" size="0.002 0.002 0.002" type="cylinder" />
                        <site euler="1.57 3.14 1.57" name="f3_dist_1" pos="0.02 0 0" rgba="25 0.5 0.7 1" size="0.002 0.002 0.002" type="cylinder" />

                    </body>


                </body>
            </body>
        </body>

        <geom class="ground" name="ground" pos="0 0 0" rgba="1 1 1 0.5" size="2 2 1" />


        <body name="object" pos="0 0 0.0555">
            <joint name="object" type="free" />
            <geom euler="0 0 0" mass="0.1" mesh="Vase1M" name="object" rgba="1 0 0 1" type="mesh" />
        </body>
    </worldbody>


    <contact>

        <pair condim="3" friction="0.3 0.3 0.005 0.0001 0.0001" geom1="object" geom2="ground" />
        <pair condim="3" friction="2 2 1.1 1.1 1.1" geom1="object" geom2="f1_prox" solimp="0.101 0.901 0.01" solref="0.004 1" />
        <pair condim="3" friction="2 2 1.1 1.1 1.1" geom1="object" geom2="f1_dist" solimp="0.101 0.901 0.01" solref="0.004 1" />
        <pair condim="3" friction="2 2 1.1 1.1 1.1" geom1="object" geom2="f2_prox" solimp="0.101 0.901 0.01" solref="0.004 1" />
        <pair condim="3" friction="2 2 1.1 1.1 1.1" geom1="object" geom2="f2_dist" solimp="0.101 0.901 0.01" solref="0.004 1" />
        <pair condim="3" friction="2 2 1.1 1.1 1.1" geom1="object" geom2="f3_prox" solimp="0.101 0.901 0.01" solref="0.004 1" />
        <pair condim="3" friction="2 2 1.1 1.1 1.1" geom1="object" geom2="f3_dist" solimp="0.101 0.901 0.01" solref="0.004 1" />
        <pair condim="3" friction="2 2 1.1 1.1 1.1" geom1="object" geom2="palm" solimp="0.101 0.901 0.01" solref="0.004 1" />

    </contact>

    <tendon>
        <fixed name="finger_1" range="0 1">
            <joint coef="1" joint="j2s7s300_joint_finger_1" />
            <joint coef="-2" joint="j2s7s300_joint_fingertip_1" />
        </fixed>
        <fixed name="finger_2" range="0 1">
            <joint coef="1" joint="j2s7s300_joint_finger_2" />
            <joint coef="-2" joint="j2s7s300_joint_fingertip_2" />
        </fixed>
        <fixed name="finger_3" range="0 1">
            <joint coef="1" joint="j2s7s300_joint_finger_3" />
            <joint coef="-2" joint="j2s7s300_joint_fingertip_3" />
        </fixed>
    </tendon>

    <equality>
        <tendon name="finger_1" tendon1="finger_1" />
        <tendon name="finger_2" tendon1="finger_2" />
        <tendon name="finger_3" tendon1="finger_3" />

    </equality>


    <actuator>

        <velocity ctrllimited="true" ctrlrange="-0.5 0.5" joint="j2s7s300_slide_x" kv="150" />
        <motor gear="25" joint="j2s7s300_slide_x" />
        <velocity ctrllimited="true" ctrlrange="-0.5 0.5" joint="j2s7s300_slide_y" kv="150" />
        <motor gear="25" joint="j2s7s300_slide_y" />
        <velocity ctrllimited="true" ctrlrange="-0.5 0.5" joint="j2s7s300_slide_z" kv="150" />
        <motor gear="25" joint="j2s7s300_slide_z" />
        <velocity ctrllimited="true" ctrlrange="-0.8 3" forcelimited="true" forcerange="0 2" joint="j2s7s300_joint_finger_1" kv="2.5" />
        <velocity ctrllimited="true" ctrlrange="-0.8 3" forcelimited="true" forcerange="0 1" joint="j2s7s300_joint_finger_2" kv="2.5" />
        <velocity ctrllimited="true" ctrlrange="-0.8 3" forcelimited="true" forcerange="0 1" joint="j2s7s300_joint_finger_3" kv="2.5" />
    </actuator>


    <sensor>

        <jointpos joint="j2s7s300_slide_x" />
        <jointpos joint="j2s7s300_slide_y" />
        <jointpos joint="j2s7s300_slide_z" />


        <jointpos joint="j2s7s300_joint_finger_1" />
        <jointpos joint="j2s7s300_joint_finger_2" />
        <jointpos joint="j2s7s300_joint_finger_3" />
        <jointpos joint="j2s7s300_joint_fingertip_1" />
        <jointpos joint="j2s7s300_joint_fingertip_2" />
        <jointpos joint="j2s7s300_joint_fingertip_3" />


        <rangefinder name="palm" site="palm" />
        <rangefinder name="palm_1" site="palm_1" />
        <rangefinder name="palm_2" site="palm_2" />
        <rangefinder name="palm_3" site="palm_3" />
        <rangefinder name="palm_4" site="palm_4" />


        <rangefinder name="finger_1_proximal" site="f1_prox" />
        <rangefinder name="finger_1_proximal_1" site="f1_prox_1" />

        <rangefinder name="finger_1_distal" site="f1_dist" />
        <rangefinder name="finger_1_distal_1" site="f1_dist_1" />

        <rangefinder name="finger_2_proximal" site="f2_prox" />
        <rangefinder name="finger_2_proximal_1" site="f2_prox_1" />

        <rangefinder name="finger_2_distal" site="f2_dist" />
        <rangefinder name="finger_2_distal_1" site="f2_dist_1" />

        <rangefinder name="finger_3_proximal" site="f3_prox" />
        <rangefinder name="finger_3_proximal_1" site="f3_prox_1" />

        <rangefinder name="finger_3_distal" site="f3_dist" />
        <rangefinder name="finger_3_distal_1" site="f3_dist_1" />

    </sensor>
</mujoco>