<mujoco model="m1n6s300">
    <compiler angle="radian" meshdir="meshes/" />
    <size njmax="500" nconmax="100" />
    <asset>
        <mesh name="base" file="base.STL" />
        <mesh name="shoulder" file="shoulder.STL" />
        <mesh name="arm_mico" file="arm_mico.STL" />
        <mesh name="forearm_mico" file="forearm_mico.STL" />
        <mesh name="wrist" file="wrist.STL" />
        <mesh name="hand_3finger" file="hand_3finger.STL" />
        <mesh name="finger_proximal" file="finger_proximal.STL" />
        <mesh name="finger_distal" file="finger_distal.STL" />
    </asset>
    <worldbody>
        <body name="root" pos="0 0 0.055">
            <camera name="camera" mode = "fixed" pos = "0 -0.1 0.1" quat = "0 -90 0 0"/>
            <inertial pos="0 0 0" mass="0.001" diaginertia="1.66667e-08 1.66667e-08 1.66667e-08" />
            <geom size="0.005 0.005 0.005" type="box" />
            <body name="m1n6s300_link_base" pos="0 0 0">
                <inertial pos="0 0 0.1255" mass="0.46784" diaginertia="0.000951271 0.000951271 0.000374272" />
                <geom type="mesh" rgba="0.792157 0.819608 0.933333 1" mesh="base" />
                <body name="m1n6s300_link_1" pos="0 0 0.15675" quat="0 0 1 0">
                    <inertial pos="0 -0.002 -0.0605" mass="0.7477" diaginertia="0.00152032 0.00152032 0.00059816" />
                    <joint name="m1n6s300_joint_1" pos="0 0 0" axis="0 0 1" limited="true" range="-6.28319 6.28319" />
                    <geom type="mesh" rgba="0.792157 0.819608 0.933333 1" mesh="shoulder" />
                    <body name="m1n6s300_link_2" pos="0 0.0016 -0.11875" quat="-0.707107 -0.707107 0 0">
                        <inertial pos="0 -0.145 -0.0076" quat="0.707107 0.707107 0 0" mass="0.85968" diaginertia="0.00467091 0.00467091 0.000386856" />
                        <joint name="m1n6s300_joint_2" pos="0 0 0" axis="0 0 1" limited="true" range="-2.35 2.35" />
                        <geom type="mesh" rgba="0.792157 0.819608 0.933333 1" mesh="arm_mico" />
                        <body name="m1n6s300_link_3" pos="0 -0.29 0" quat="0 -1 0 0">
                            <inertial pos="0 0.0463 -0.0065" quat="0.707107 0.707107 0 0" mass="0.606" diaginertia="0.000383798 0.000383798 0.0001212" />
                            <joint name="m1n6s300_joint_3" pos="0 0 0" axis="0 0 1" limited="true" range="-2.86 2.86" />
                            <geom type="mesh" rgba="0.792157 0.819608 0.933333 1" mesh="forearm_mico" />
                            <body name="m1n6s300_link_4" pos="0 0.1231 -0.0086" quat="0 0 -0.707107 0.707107">
                                <inertial pos="0 -0.037 -0.0642" quat="0.5 0.5 -0.5 0.5" mass="0.1785" diaginertia="0.0001428 7.73497e-05 7.73497e-05" />
                                <joint name="m1n6s300_joint_4" pos="0 0 0" axis="0 0 1" limited="true" range="-6.28319 6.28319" />
                                <geom type="mesh" rgba="0.792157 0.819608 0.933333 1" mesh="wrist" />
                                <body name="m1n6s300_link_5" pos="0 -0.03703 -0.06414" quat="0 0 0.5 0.866025">
                                    <inertial pos="0 -0.037 -0.0642" quat="0.5 0.5 -0.5 0.5" mass="0.1785" diaginertia="0.0001428 7.73497e-05 7.73497e-05" />
                                    <joint name="m1n6s300_joint_5" pos="0 0 0" axis="0 0 1" limited="true" range="-6.28319 6.28319" />
                                    <geom type="mesh" rgba="0.792157 0.819608 0.933333 1" mesh="wrist" />
                                    <body name="m1n6s300_link_6" pos="0 -0.03703 -0.06414" quat="0 0 0.5 0.866025">
                                        <inertial pos="0 0 -0.06" quat="0.5 0.5 -0.5 0.5" mass="0.727" diaginertia="0.0005816 0.000345324 0.000345324" />
                                        <joint name="m1n6s300_joint_6" pos="0 0 0" axis="0 0 1" limited="true" range="-6.28319 6.28319" />
                                        <geom type="mesh" rgba="0.792157 0.819608 0.933333 1" mesh="hand_3finger" />
                                        <body name="m1n6s300_end_effector" pos="0 0 -0.16" quat="0 1 0 0">
                                            <inertial pos="0 0 -0.16" quat="0 1 0 0" mass="0" diaginertia="0 0 0" />
                                        </body>
                                        <body name="m1n6s300_link_finger_1" pos="0.00279 0.03126 -0.11467" quat="0.379408 -0.662973 -0.245899 0.596699">
                                            <inertial pos="0.022 0 0" mass="0.01" diaginertia="7.89997e-07 7.89997e-07 8e-08" />
                                            <joint name="m1n6s300_joint_finger_1" pos="0 0 0" axis="0 0 1" limited="true" range="0 2" />
                                            <geom type="mesh" rgba="0.792157 0.819608 0.933333 1" mesh="finger_proximal" />
                                            <body name="m1n6s300_link_finger_tip_1" pos="0.044 -0.003 0">
                                                <inertial pos="0.022 0 0" mass="0.01" diaginertia="7.89997e-07 7.89997e-07 8e-08" />
                                                <geom type="mesh" rgba="0.792157 0.819608 0.933333 1" mesh="finger_distal" />
                                            </body>
                                        </body>
                                        <body name="m1n6s300_link_finger_2" pos="0.02226 -0.02707 -0.11482" quat="0.659653 -0.37146 0.601679 -0.254671">
                                            <inertial pos="0.022 0 0" mass="0.01" diaginertia="7.89997e-07 7.89997e-07 8e-08" />
                                            <joint name="m1n6s300_joint_finger_2" pos="0 0 0" axis="0 0 1" limited="true" range="0 2" />
                                            <geom type="mesh" rgba="0.792157 0.819608 0.933333 1" mesh="finger_proximal" />
                                            <body name="m1n6s300_link_finger_tip_2" pos="0.044 -0.003 0">
                                                <inertial pos="0.022 0 0" mass="0.01" diaginertia="7.89997e-07 7.89997e-07 8e-08" />
                                                <geom type="mesh" rgba="0.792157 0.819608 0.933333 1" mesh="finger_distal" />
                                            </body>
                                        </body>
                                        <body name="m1n6s300_link_finger_3" pos="-0.02226 -0.02707 -0.11482" quat="0.601679 -0.254671 0.659653 -0.37146">
                                            <inertial pos="0.022 0 0" mass="0.01" diaginertia="7.89997e-07 7.89997e-07 8e-08" />
                                            <joint name="m1n6s300_joint_finger_3" pos="0 0 0" axis="0 0 1" limited="true" range="0 2" />
                                            <geom type="mesh" rgba="0.792157 0.819608 0.933333 1" mesh="finger_proximal" />
                                            <body name="m1n6s300_link_finger_tip_3" pos="0.044 -0.003 0">
                                                <inertial pos="0.022 0 0" mass="0.01" diaginertia="7.89997e-07 7.89997e-07 8e-08" />
                                                <geom type="mesh" rgba="0.792157 0.819608 0.933333 1" mesh="finger_distal" />
                                            </body>
                                        </body>
                                    </body>
                                </body>
                            </body>
                        </body>
                    </body>
                </body>
            </body>
        </body>
        <body name="floor" pos="0 0 -0.01">
            <geom condim="3" size="2.0 2.0 0.02" rgba="0 1 0 1" type="box"/>
        </body>
        <body name="cube" pos="0.5 0.0 0.0375">
            <joint type="free"/>
            <geom name="cube" mass="0.0884" size="0.0375 0.0375 0.0375" rgba="1 0 0 1" type="box"/> 
<!--             M(1,1), M(2,2), M(3,3), M(1,2), M(1,3), M(2,3) -->
<!--             <inertial pos="-0.0011 0.0029 0.0055" mass="0.0884" diaginertia="0.0001 0.000093 0.000083" /> -->
        </body>
    </worldbody>
    <actuator>
        <velocity joint="m1n6s300_joint_1" kv="10" forcelimited="true" forcerange="-2000 2000" ctrllimited="true" ctrlrange="-6.28319 6.28319"></velocity>
        <velocity joint="m1n6s300_joint_2" kv="40" forcelimited="true" forcerange="-2000 2000" ctrllimited="true" ctrlrange="-2.35 2.35"></velocity>
        <velocity joint="m1n6s300_joint_3" kv="10" forcelimited="true" forcerange="-2000 2000" ctrllimited="true" ctrlrange="-2.86 2.86"></velocity>
        <velocity joint="m1n6s300_joint_4" kv="4" forcelimited="true" forcerange="-2000 2000" ctrllimited="true" ctrlrange="-6.28319 6.28319"></velocity>
        <velocity joint="m1n6s300_joint_5" kv="4" forcelimited="true" forcerange="-2000 2000" ctrllimited="true" ctrlrange="-6.28319 6.28319"></velocity>
        <velocity joint="m1n6s300_joint_6" kv="2" forcelimited="true" forcerange="-2000 2000" ctrllimited="true" ctrlrange="-6.28319 6.28319"></velocity>
        <position joint="m1n6s300_joint_finger_1" kp="5"  ctrllimited="true" ctrlrange="0 2"></position>
        <position joint="m1n6s300_joint_finger_2" kp="5"  ctrllimited="true" ctrlrange="0 2"></position>
        <position joint="m1n6s300_joint_finger_3" kp="5"  ctrllimited="true" ctrlrange="0 2"></position>
    </actuator>
    <sensor>
        <jointpos joint='m1n6s300_joint_1'/>
        <jointpos joint='m1n6s300_joint_2'/>
        <jointpos joint='m1n6s300_joint_3'/>
        <jointpos joint='m1n6s300_joint_4'/>
        <jointpos joint='m1n6s300_joint_5'/>
        <jointpos joint='m1n6s300_joint_6'/>
        <jointpos joint='m1n6s300_joint_finger_1'/>
        <jointpos joint='m1n6s300_joint_finger_2'/>
        <jointpos joint='m1n6s300_joint_finger_3'/>
    </sensor>
</mujoco>
